Workbook

Sheet CRIs
A1: CRIs Solfácil — comparativo das seis emissões
A2: Estrutura conforme termos de securitização e prospectos; carteira e inadimplência conforme informe mensal de CRI de 31/08/2026 no Fundos.NET.
A4: Indicador | B4: CRI I | C4: CRI II | D4: CRI III | E4: CRI IV | F4: CRI V | G4: CRI VI
A5: IDENTIFICAÇÃO
A6: Securitizadora | B6: Kanastra | C6: Kanastra | D6: Kanastra | E6: Kanastra | F6: Vert | G6: Vert
A7: Nº da emissão | B7: 1ª | C7: 2ª | D7: 3ª | E7: 4ª | F7: 174ª | G7: 177ª
A8: Data de emissão | B8: 15/01/2024 | C8: 25/06/2024 | D8: 28/05/2025 | E8: 28/09/2025 | F8: 20/05/2026 | G8: 21/07/2026
A9: Registro CVM | B9: 16/02/2024 | C9: 21/06/2024 | D9: 03/06/2025 | E9: 29/09/2025 | F9: 20/05/2026 | G9: 20/07/2026
A10: Encerramento da oferta | B10: 23/02/2024 | C10: 28/06/2024 | D10: 06/06/2025 | E10: 13/10/2025 | F10: 28/05/2026 | G10: 02/09/2026
A11: Coordenador líder | B11: Itaú BBA | C11: Itaú BBA | D11: Itaú BBA | E11: Itaú BBA | F11: XP | G11: XP e Bradesco BBI
A12: Agente fiduciário | B12: Vórtx | C12: Oliveira Trust | D12: Oliveira Trust | E12: Oliveira Trust | F12: Oliveira Trust | G12: Oliveira Trust
A13: Rating da camada de topo | B13: AA+sf(bra) / AAsf(bra) (Fitch) | C13: AAA (Moody's) / AA+ (Fitch) | D13: AAA (Moody's) | E13: AAA (Moody's) | F13: AAA (Moody's) | G13: Sem rating
A14: Volume total emitido (R$ mm) | B14: =SUM('Séries'!D6:D10) -> 600 | C14: =SUM('Séries'!D12:D16) -> 750 | D14: =SUM('Séries'!D18:D23) -> 750 | E14: =SUM('Séries'!D25:D31) -> 450 | F14: =SUM('Séries'!D33:D38) -> 470.599 | G14: =SUM('Séries'!D40:D44) -> 450
A15: Nº de séries | B15: 5 | C15: 5 | D15: 6 | E15: 7 | F15: 6 | G15: 5
A16: SUBORDINAÇÃO NA EMISSÃO
A17: Camada de topo | B17: Super Sênior | C17: Super Sênior | D17: Super Sênior | E17: Super Sênior | F17: Super Sênior | G17: Sênior A e B
A18: Peso da camada de topo | B18: =SUM('Séries'!D6:D6)/SUM('Séries'!D6:D10) -> 0.6 | C18: =SUM('Séries'!D12:D12)/SUM('Séries'!D12:D16) -> 0.65 | D18: =SUM('Séries'!D18:D19)/SUM('Séries'!D18:D23) -> 0.65 | E18: =SUM('Séries'!D25:D26)/SUM('Séries'!D25:D31) -> 0.65 | F18: =SUM('Séries'!D33:D34)/SUM('Séries'!D33:D38) -> 0.70000149 | G18: =SUM('Séries'!D40:D41)/SUM('Séries'!D40:D44) -> 0.85
A19: Subordinação abaixo do topo | B19: =1-SUM('Séries'!D6:D6)/SUM('Séries'!D6:D10) -> 0.4 | C19: =1-SUM('Séries'!D12:D12)/SUM('Séries'!D12:D16) -> 0.35 | D19: =1-SUM('Séries'!D18:D19)/SUM('Séries'!D18:D23) -> 0.35 | E19: =1-SUM('Séries'!D25:D26)/SUM('Séries'!D25:D31) -> 0.35 | F19: =1-SUM('Séries'!D33:D34)/SUM('Séries'!D33:D38) -> 0.29999851 | G19: =1-SUM('Séries'!D40:D41)/SUM('Séries'!D40:D44) -> 0.15
A20: Subordinação abaixo da 2ª camada | B20: =1-SUM('Séries'!D6:D7)/SUM('Séries'!D6:D10) -> 0.25 | C20: =1-SUM('Séries'!D12:D13)/SUM('Séries'!D12:D16) -> 0.17 | D20: =1-SUM('Séries'!D18:D20)/SUM('Séries'!D18:D23) -> 0.17 | E20: =1-SUM('Séries'!D25:D28)/SUM('Séries'!D25:D31) -> 0.17 | F20: =1-SUM('Séries'!D33:D35)/SUM('Séries'!D33:D38) -> 0.14999819 | G20: =1-SUM('Séries'!D40:D42)/SUM('Séries'!D40:D44) -> 0.07
A21: Razão de cobertura mínima — camada de topo | B21: – | C21: 159 | D21: 158.73 | E21: 158.73 | F21: 147.06 | G21: 120.48
A22: Razão de cobertura mínima — 2ª camada | B22: – | C22: 123 | D22: 123.46 | E22: 123.46 | F22: 120.48 | G22: 109.89
A23: Razão de cobertura mínima — 3ª camada | B23: – | C23: 110 | D23: 109.89 | E23: 109.89 | F23: 109.89 | G23: 105.26
A24: Razão de cobertura mínima — 4ª camada | B24: – | C24: 105 | D24: 105.26 | E24: 105.26 | F24: 105.26 | G24: –
A25: Subordinação implícita no covenant do topo | B25: – | C25: 0.37106918 | D25: 0.36999937 | E25: 0.36999937 | F25: 0.32000544 | G25: 0.16998672
A26: RETORNO E EXCESSO DE SPREAD
A27: Taxa mínima da carteira (elegibilidade) | B27: 21.5 | C27: 21 | D27: 22 | E27: 21 | F27: 21 | G27: 21.5
A28: Custo médio ponderado das séries públicas | B28: 13.092755 | C28: 14.544458 | D28: 16.423711 | E28: 15.329082 | F28: 15.295173 | G28: 16.071535
A29: Excesso de spread bruto (p.p.) | B29: 8.4072449 | C29: 6.4555423 | D29: 5.5762887 | E29: 5.6709175 | F29: 5.7048266 | G29: 5.4284651
A30: CRITÉRIOS DE ELEGIBILIDADE
A31: Prazo máximo do recebível | B31: 3.845 dias (≈126 meses) | C31: 3.845 dias (≈126 meses) | D31: 3.845 dias (≈126 meses) | E31: 3.845 dias (≈126 meses) | F31: 3.845 dias (≈126 meses) | G31: 3.845 dias (≈126 meses)
A32: Prazo médio ponderado máximo | B32: 2.000 dias (≈66 meses) | C32: 2.000 dias (≈66 meses) | D32: 2.000 dias (≈66 meses) | E32: 2.000 dias (≈66 meses) | F32: 2.000 dias (≈66 meses) | G32: 2.000 dias (≈66 meses)
A33: Carência máxima da CCB | B33: 185 dias | C33: 185 dias | D33: 185 dias | E33: 185 dias | F33: 185 dias | G33: 185 dias
A34: Idade máxima do devedor PF | B34: 71 anos | C34: 71 anos | D34: 71 anos | E34: 71 anos | F34: 71 anos | G34: 71 anos
A35: Requisito do devedor PJ | B35: Constituído há ≥ 2 anos | C35: Constituído há ≥ 2 anos | D35: Constituído há ≥ 2 anos | E35: Constituído há ≥ 2 anos | F35: Constituído há ≥ 2 anos | G35: Constituído há ≥ 2 anos
A36: Teto por devedor PF (R$ mil) | B36: 350 | C36: 350 | D36: 350 | E36: 350 | F36: 350 | G36: 350
A37: Teto por devedor PJ (R$ mil) | B37: 600 | C37: 600 | D37: 700 | E37: 700 | F37: 700 | G37: 700
A38: Concentração máxima por devedor | B38: 0,10% do patrimônio separado | C38: 0,10% do patrimônio separado | D38: 0,10% do patrimônio separado | E38: 0,25% do patrimônio separado | F38: 0,15% caindo a 0,07% | G38: 0,11% do valor da emissão
A39: Revolvência | B39: Não | C39: Não | D39: Não | E39: Não | F39: Não | G39: Não
A40: Regime fiduciário | B40: Sim | C40: Sim | D40: Sim | E40: Sim | F40: Sim | G40: Sim
A41: Lastro | B41: CCB pré-fixada de financiamento de Sistema Solar | C41: CCB pré-fixada de financiamento de Sistema Solar | D41: CCB pré-fixada de financiamento de Sistema Solar | E41: CCB pré-fixada de financiamento de Sistema Solar | F41: CCB pré-fixada de financiamento de Sistema Solar | G41: CCB pré-fixada de financiamento de Sistema Solar
...

Sheet Séries
A1: Séries por emissão — valores integralizados
A2: Valores em R$ milhões, em azul as entradas. Custo a.a. converte as séries pós-fixadas ao CDI da célula B3.
A3: CDI de referência (% a.a.) | B3: 13.65
A5: Emissão | B5: Série | C5: Camada | D5: R$ mm | E5: % do total | F5: Remuneração | G5: Custo a.a. (%) | H5: Vencimento | I5: ISIN | J5: Colocação
A6: CRI I | B6: 1ª | C6: Super Sênior | D6: 360 | E6: =D6/SUM($D$6:$D$10) -> 0.6 | F6: Pré 11,51% | G6: 11.51 | H6: – | I6: BRKNSTCRI000 | J6: Pública
A7: CRI I | B7: 2ª | C7: Sênior | D7: 90 | E7: =D7/SUM($D$6:$D$10) -> 0.15 | F7: Pré 12,74% | G7: 12.74 | H7: – | I7: BRKNSTCRI018 | J7: Pública
A8: CRI I | B8: 3ª | C8: Mezanino | D8: 108 | E8: =D8/SUM($D$6:$D$10) -> 0.18 | F8: Pré 16,48% | G8: 16.48 | H8: – | I8: BRKNSTCRI026 | J8: Pública
A9: CRI I | B9: 4ª | C9: Subordinado | D9: 30 | E9: =D9/SUM($D$6:$D$10) -> 0.05 | F9: Pré 20,95% | G9: 20.95 | H9: – | I9: BRKNSTCRI034 | J9: Pública
A10: CRI I | B10: 5ª | C10: Subordinado Jr (privada) | D10: 12 | E10: =D10/SUM($D$6:$D$10) -> 0.02 | F10: 9,86% (informe) | G10: 9.86 | H10: – | I10: – | J10: Privada
A12: CRI II | B12: 1ª | C12: Super Sênior | D12: 487.5 | E12: =D12/SUM($D$12:$D$16) -> 0.65 | F12: Pré 13,1926% | G12: 13.1926 | H12: 15/01/2031 | I12: BRKNSTCRI059 | J12: Pública
A13: CRI II | B13: 2ª | C13: Sênior | D13: 135 | E13: =D13/SUM($D$12:$D$16) -> 0.18 | F13: Pré 14,5663% | G13: 14.5663 | H13: 15/01/2031 | I13: BRKNSTCRI067 | J13: Pública
A14: CRI II | B14: 3ª | C14: Mezanino | D14: 75 | E14: =D14/SUM($D$12:$D$16) -> 0.1 | F14: CDI + 6,00% | G14: 19.65 | H14: 15/01/2034 | I14: BRKNSTCRI075 | J14: Pública
A15: CRI II | B15: 4ª | C15: Subordinado | D15: 30 | E15: =D15/SUM($D$12:$D$16) -> 0.04 | F15: CDI + 10,00% | G15: 23.65 | H15: 15/01/2034 | I15: BRKNSTCRI083 | J15: Pública
A16: CRI II | B16: 5ª | C16: Subordinado Jr (privada) | D16: 22.5 | E16: =D16/SUM($D$12:$D$16) -> 0.03 | F16: n.d. | G16: n.d. | H16: 15/01/2036 | I16: – | J16: Privada
A18: CRI III | B18: 1ª | C18: Super Sênior A | D18: 367.5 | E18: =D18/SUM($D$18:$D$23) -> 0.49 | F18: Pré 15,50% | G18: 15.5 | H18: – | I18: BRKNSTCRI0A4 | J18: Pública
A19: CRI III | B19: 2ª | C19: Super Sênior B | D19: 120 | E19: =D19/SUM($D$18:$D$23) -> 0.16 | F19: Pré 15,50% | G19: 15.5 | H19: – | I19: BRKNSTCRI0B2 | J19: Pública
A20: CRI III | B20: 3ª | C20: Sênior | D20: 135 | E20: =D20/SUM($D$18:$D$23) -> 0.18 | F20: Pré 16,50% | G20: 16.5 | H20: – | I20: BRKNSTCRI0C0 | J20: Pública
A21: CRI III | B21: 4ª | C21: Mezanino | D21: 75 | E21: =D21/SUM($D$18:$D$23) -> 0.1 | F21: CDI + 5,75% | G21: 19.4 | H21: – | I21: BRKNSTCRI0D8 | J21: Pública
A22: CRI III | B22: 5ª | C22: Subordinado | D22: 30 | E22: =D22/SUM($D$18:$D$23) -> 0.04 | F22: CDI + 10,00% | G22: 23.65 | H22: – | I22: BRKNSTCRI0E6 | J22: Pública
A23: CRI III | B23: 6ª | C23: Subordinado Jr (privada) | D23: 22.5 | E23: =D23/SUM($D$18:$D$23) -> 0.03 | F23: n.d. | G23: n.d. | H23: – | I23: – | J23: Privada
A25: CRI IV | B25: 1ª | C25: Super Sênior A | D25: 195 | E25: =D25/SUM($D$25:$D$31) -> 0.43333333 | F25: Pré 14,2216% | G25: 14.2216 | H25: 20/09/2030 | I25: BRKNSTCRI0G1 | J25: Pública
A26: CRI IV | B26: 2ª | C26: Super Sênior B | D26: 97.5 | E26: =D26/SUM($D$25:$D$31) -> 0.21666667 | F26: Pré 14,2216% | G26: 14.2216 | H26: 20/09/2030 | I26: BRKNSTCRI0K3 | J26: Pública
A27: CRI IV | B27: 3ª | C27: Sênior A | D27: 54 | E27: =D27/SUM($D$25:$D$31) -> 0.12 | F27: Pré 15,3565% | G27: 15.3565 | H27: 22/09/2033 | I27: BRKNSTCRI0H9 | J27: Pública
A28: CRI IV | B28: 4ª | C28: Sênior B | D28: 27 | E28: =D28/SUM($D$25:$D$31) -> 0.06 | F28: Pré 15,3565% | G28: 15.3565 | H28: 22/09/2033 | I28: BRKNSTCRI0M9 | J28: Pública
A29: CRI IV | B29: 5ª | C29: Mezanino | D29: 45 | E29: =D29/SUM($D$25:$D$31) -> 0.1 | F29: CDI + 5,50% | G29: 19.15 | H29: 24/09/2035 | I29: BRKNSTCRI0I7 | J29: Pública
A30: CRI IV | B30: 6ª | C30: Subordinado | D30: 18 | E30: =D30/SUM($D$25:$D$31) -> 0.04 | F30: CDI + 10,00% | G30: 23.65 | H30: 24/09/2035 | I30: BRKNSTCRI0J5 | J30: Pública
A31: CRI IV | B31: 7ª | C31: Subordinado Jr (privada) | D31: 13.5 | E31: =D31/SUM($D$25:$D$31) -> 0.03 | F31: CDI + 13,2480% | G31: 26.898 | H31: 22/09/2037 | I31: BRKNSTCRI0N7 | J31: Privada
A33: CRI V | B33: 1ª | C33: Super Sênior A | D33: 103.87 | E33: =D33/SUM($D$33:$D$38) -> 0.2207187 | F33: Pré 14,8064% | G33: 14.8064 | H33: 20/05/2031 | I33: BRVERTCRIDZ7 | J33: Pública
A34: CRI V | B34: 2ª | C34: Super Sênior B | D34: 225.55 | E34: =D34/SUM($D$33:$D$38) -> 0.47928279 | F34: 104% do CDI | G34: 14.196 | H34: 20/05/2031 | I34: BRVERTCRIE08 | J34: Pública
A35: CRI V | B35: 3ª | C35: Sênior | D35: 70.59 | E35: =D35/SUM($D$33:$D$38) -> 0.15000032 | F35: Pré 15,7760% | G35: 15.776 | H35: 22/05/2034 | I35: BRVERTCRIE16 | J35: Pública
A36: CRI V | B36: 4ª | C36: Mezanino | D36: 37.647 | E36: =D36/SUM($D$33:$D$38) -> 0.079998045 | F36: CDI + 5,50% | G36: 19.15 | H36: 20/05/2036 | I36: BRVERTCRIE24 | J36: Pública
A37: CRI V | B37: 5ª | C37: Subordinado | D37: 18.824 | E37: =D37/SUM($D$33:$D$38) -> 0.040000085 | F37: CDI + 8,00% | G37: 21.65 | H37: 20/05/2036 | I37: BRVERTCRIE32 | J37: Pública
A38: CRI V | B38: 6ª | C38: Subordinado Jr (privada) | D38: 14.118 | E38: =D38/SUM($D$33:$D$38) -> 0.030000064 | F38: Pré 14,06% | G38: 14.06 | H38: – | I38: – | J38: Privada
A40: CRI VI | B40: 1ª | C40: Sênior A | D40: 100 | E40: =D40/SUM($D$40:$D$44) -> 0.22222222 | F40: CDI + 1,50% | G40: 15.15 | H40: 20/05/2031 | I40: BRVERTCRIEC4 | J40: Pública
A41: CRI VI | B41: 2ª | C41: Sênior B | D41: 282.5 | E41: =D41/SUM($D$40:$D$44) -> 0.62777778 | F41: CDI + 2,00% | G41: 15.65 | H41: 21/07/2031 | I41: BRVERTCRIED2 | J41: Pública
A42: CRI VI | B42: 3ª | C42: Mezanino I | D42: 36 | E42: =D42/SUM($D$40:$D$44) -> 0.08 | F42: CDI + 5,50% | G42: 19.15 | H42: 21/07/2036 | I42: BRVERTCRIEE0 | J42: Pública
A43: CRI VI | B43: 4ª | C43: Mezanino II | D43: 18 | E43: =D43/SUM($D$40:$D$44) -> 0.04 | F43: CDI + 8,00% | G43: 21.65 | H43: 21/07/2036 | I43: BRVERTCRIEF7 | J43: Pública
A44: CRI VI | B44: 5ª | C44: Subordinada (privada) | D44: 13.5 | E44: =D44/SUM($D$40:$D$44) -> 0.03 | F44: 100% do CDI | G44: 13.65 | H44: 20/07/2038 | I44: BRVERTCRIEG5 | J44: Privada

Sheet Notas
A1: Notas, definições e fontes
A3: Perímetro | B3: Seis emissões de CRI com lastro declarado em CCB originadas na Plataforma Solfácil: Kanastra 1ª a 4ª e Vert 174ª e 177ª. Identificadas na base de ofertas encerradas sob a Resolução CVM 160 e confirmadas no Fundos.NET.
A4: Lastro | B4: Em todas as seis, o critério de elegibilidade exige CCB pré-fixada cujo recurso tenha destinação específica à aquisição de Sistema Solar em imóvel. Sistema Solar é definido como o conjunto de placas fotovoltaicas, equipamentos e sistemas acessórios para geração, armazenamento e utilização de energia solar, instalado por Integradores Solares. Nenhuma das emissões admite outro tipo de bem financiado.
A5: Cadeia de originação | B5: A Solfácil Energia Solar Tecnologia e Serviços Financeiros é a originadora: opera a plataforma, faz a análise de crédito e seleciona os recebíveis. A CCB é emitida pelo devedor em favor de um Endossante Inicial — a BMP Sociedade de Crédito Direto e a Solfácil SCD, depois Solfácil SCFI. Os Integradores Solares são empresas terceiras aprovadas na plataforma, responsáveis por vender e instalar o sistema.
A6: Equipamento | B6: O equipamento não é da Solfácil. Quem fornece e instala é o Integrador Solar. A Solfácil financia a operação e os documentos preveem alienação fiduciária dos equipamentos descritos na CCB, sem registro prévio em cartório.
A7: Subordinação na emissão | B7: Soma das séries abaixo da camada em questão, dividida pelo total emitido, incluindo a série de colocação privada subscrita pela Solfácil.
A8: Razão de cobertura | B8: Valor presente dos direitos creditórios líquido de PDD mais ativo financeiro, dividido pelo saldo devedor acumulado das séries até aquela camada. Apurada diariamente pela emissora e informada no informe mensal.
A9: Subordinação implícita | B9: 1 menos o inverso da razão de cobertura mínima. Difere da subordinação na emissão porque o numerador do covenant é a carteira, que é maior que a emissão.
A10: Excesso de spread | B10: Taxa mínima contratual da carteira menos o custo médio ponderado das séries públicas. Séries pós-fixadas convertidas ao CDI de 13,65% a.a. (Selic de setembro de 2026, série 4389 do BCB).
A11: NPL acima de 90 dias | B11: Soma das faixas de atraso de 91 a 120, 121 a 150, 151 a 180, 181 a 360 e acima de 361 dias do informe mensal de CRI.
A12: Fontes | B12: Prospectos definitivos e termos de securitização registrados na CVM (processos SRE/0104/2024, SRE/1471/2024, SRE/1111/2025, SRE/2711/2025, SRE/1197/2026 e SRE/2316/2026); informes mensais de CRI de 08/2026 no Fundos.NET; base de ofertas públicas encerradas em dados.cvm.gov.br. Consulta em 19/10/2026.
