Workbook

Sheet Comparativo
A1: Solfácil — comparativo de operações
A2: Indicadores de carteira e estrutura na competência de agosto de 2026. Linhas derivadas calculadas por fórmula sobre a aba Dados.
A4: Indicador | B4: FIDC III | C4: FIDC VI | D4: FIDC VII | E4: FIDC VIII | F4: CRI II | G4: CRI IV | H4: CRI VI
A5: Tipo | B5: Derivativo | C5: Cota Sr. | D5: Derivativo | E5: n.d. | F5: Super Sr / Sr | G5: Derivativo | H5: Derivativo
A6: PL / Valor total (R$ mm) | B6: ='Dados'!B5 -> 133.74889 | C6: ='Dados'!C5 -> 145.18464 | D6: ='Dados'!D5 -> 619.10189 | E6: ='Dados'!E5 -> 750 | F6: ='Dados'!F5 -> 750 | G6: ='Dados'!G5 -> 450 | H6: ='Dados'!H5 -> 450
A7: Duration (meses) | B7: ='Dados'!B14 -> 12 | C7: ='Dados'!C14 -> 17 | D7: ='Dados'!D14 -> 16 | E7: ='Dados'!E14 -> 24 | F7: ='Dados'!F14 -> 14 | G7: ='Dados'!G14 -> 48 | H7: ='Dados'!H14 -> 27
A8: Sub / PL em Ago-26 | B8: ='Dados'!B6/'Dados'!B5 -> 0.32869616 | C8: ='Dados'!C6/'Dados'!C5 -> 0.25191409 | D8: ='Dados'!D6/'Dados'!D5 -> 0.26197221 | E8: ='Dados'!E6/'Dados'!E5 -> 0.25 | F8: ='Dados'!F6/'Dados'!F5 -> 0.35 | G8: ='Dados'!G6/'Dados'!G5 -> 0.35 | H8: ='Dados'!H6/'Dados'!H5 -> 0.15
A9: Cobertura PDD / NPL > 90d | B9: =IF('Dados'!B10=0,"n.a.",'Dados'!B8/'Dados'!B10) -> 4.4979754 | C9: =IF('Dados'!C10=0,"n.a.",'Dados'!C8/'Dados'!C10) -> 5.3900237 | D9: =IF('Dados'!D10=0,"n.a.",'Dados'!D8/'Dados'!D10) -> 15.651161 | E9: n.d. | F9: =IF('Dados'!F10=0,"n.a.",'Dados'!F8/'Dados'!F10) -> 3.0651691 | G9: =IF('Dados'!G10=0,"n.a.",'Dados'!G8/'Dados'!G10) -> 5.989765 | H9: =IF('Dados'!H10=0,"n.a.",'Dados'!H8/'Dados'!H10) -> n.a.
A10: Vencidos / Carteira | B10: ='Dados'!B9/'Dados'!B7 -> 0.033704841 | C10: ='Dados'!C9/'Dados'!C7 -> 0.11472982 | D10: ='Dados'!D9/'Dados'!D7 -> 0.0030958759 | E10: n.d. | F10: ='Dados'!F9/'Dados'!F7 -> 0.060918706 | G10: ='Dados'!G9/'Dados'!G7 -> 0.015119591 | H10: ='Dados'!H9/'Dados'!H7 -> 0.0033215289
A11: NPL > 90d / Carteira | B11: ='Dados'!B10/'Dados'!B7 -> 0.012624144 | C11: ='Dados'!C10/'Dados'!C7 -> 0.065230648 | D11: ='Dados'!D10/'Dados'!D7 -> 0.000310021 | E11: n.d. | F11: ='Dados'!F10/'Dados'!F7 -> 0.03928369 | G11: ='Dados'!G10/'Dados'!G7 -> 0.0068874947 | H11: ='Dados'!H10/'Dados'!H7 -> 0
A12: Base subordinada (R$ mm) | B12: ='Dados'!B6 -> 43.962746 | C12: ='Dados'!C6 -> 36.574058 | D12: ='Dados'!D6 -> 162.18749 | E12: ='Dados'!E6 -> 187.5 | F12: ='Dados'!F6 -> 262.5 | G12: ='Dados'!G6 -> 157.5 | H12: ='Dados'!H6 -> 67.5
A13: Rating Sr | B13: AA+ (Fitch) | C13: brAA (Austin) | D13: – | E13: – | F13: AAA (Moody's) / AA+ (Fitch) | G13: AAA (Moody's) | H13: Sem rating
A14: Rating Mezanino A | B14: BBB (Fitch) | C14: – | D14: – | E14: – | F14: AA− (Moody's) | G14: AA− (Moody's) | H14: Sem rating
A15: Preço Cota Sr. | B15: CDI + 3,5% | C15: CDI + 3,5% | D15: CDI + 2,0% | E15: CDI + 1,75% | F15: Pré 13,1926% a.a. | G15: Pré 14,2216% a.a. | H15: CDI + 1,5% / CDI + 2,0%
A17: Definições. Sub / PL = base subordinada ÷ linha PL / Valor total; nos FIDCs a base subordinada é mezanino + júnior sobre o PL, nos CRIs é a soma das séries abaixo da camada de topo sobre o valor emitido. Vencidos = saldo de direitos creditórios em atraso em todas as faixas. NPL > 90d = faixas acima de 90 dias. Carteira = direitos creditórios a vencer mais em atraso, antes da PDD. Não há FIDC Solfácil VIII registrado na CVM até 19/10/2026: a coluna reproduz os valores da planilha de origem e não foi verificada em fonte pública.

Sheet Dados
A1: Insumos — base 31/08/2026
A2: Valores em R$ milhões. Células em azul são entradas. FIDC: informe mensal FIDC (dados.cvm.gov.br), tabelas I, IV, V e X.2. CRI: informe mensal de CRI de 08/2026 no Fundos.NET. Ratings e taxas: prospectos definitivos e termos de securitização registrados na CVM.
A4: Insumo | B4: FIDC III | C4: FIDC VI | D4: FIDC VII | E4: FIDC VIII | F4: CRI II | G4: CRI IV | H4: CRI VI
A5: PL (FIDC) / valor total emitido (CRI) | B5: 133.74889 | C5: 145.18464 | D5: 619.10189 | E5: 750 | F5: 750 | G5: 450 | H5: 450
A6: Base subordinada | B6: 43.962746 | C6: 36.574058 | D6: 162.18749 | E6: 187.5 | F6: 262.5 | G6: 157.5 | H6: 67.5
A7: Carteira de direitos creditórios | B7: 132.36351 | C7: 218.16956 | D7: 554.88174 | E7: n.d. | F7: 389.831 | G7: 383.013 | H7: 445.879
A8: PDD | B8: 7.516009 | C8: 76.70727 | D8: 2.692391 | E8: n.d. | F8: 46.94 | G8: 15.801 | H8: 0.494
A9: Saldo em atraso (todas as faixas) | B9: 4.461291 | C9: 25.030555 | D9: 1.717845 | E9: n.d. | F9: 23.748 | G9: 5.791 | H9: 1.481
A10: Saldo em atraso acima de 90 dias | B10: 1.670976 | C10: 14.231342 | D10: 0.172025 | E10: n.d. | F10: 15.314 | G10: 2.638 | H10: 0
A11: Saldo da camada sênior | B11: 89.786144 | C11: 108.61059 | D11: 456.9144 | E11: n.d. | F11: 487.5 | G11: 292.5 | H11: 382.5
A12: Cotas mezanino (FIDC) | B12: 28.182698 | C12: 30.473428 | D12: 129.01285 | E12: n.d. | F12: n.d. | G12: n.d. | H12: n.d.
A13: Cotas júnior (FIDC) | B13: 15.780047 | C13: 6.100631 | D13: 33.174639 | E13: n.d. | F13: n.d. | G13: n.d. | H13: n.d.
A14: Duration da carteira (meses) | B14: 12 | C14: 17 | D14: 16 | E14: 24 | F14: 14 | G14: 48 | H14: 27

Sheet Validação
A1: Validação contra a planilha de origem
A3: Coluna | B3: Indicador | C3: Planilha de origem | D3: Apurado (ago/2026) | E3: Situação | F3: Observação
A4: FIDC III | B4: PL | C4: 134 | D4: 133,7 | E4: confere
A5: FIDC III | B5: Base subordinada | C5: 44,0 | D5: 44,0 | E5: confere
A6: FIDC III | B6: Sub / PL | C6: 33% | D6: 32,9% | E6: confere
A7: FIDC III | B7: Vencidos / Carteira | C7: 3% | D7: 3,4% | E7: confere
A8: FIDC III | B8: NPL > 90d / Carteira | C8: 1% | D8: 1,3% | E8: confere
A9: FIDC III | B9: Cobertura PDD / NPL | C9: 450% | D9: 450% | E9: confere | F9: Bate na casa decimal: PDD 7,516 ÷ NPL>90d 1,671.
A10: FIDC III | B10: Rating Sr / Mez A | C10: AA+ / BBB (Fitch) | D10: AA+sf(bra) / BBBsf(bra) | E10: confere | F10: Relatório Fitch de 12/11/2025, perspectiva positiva.
A11: FIDC VI | B11: PL | C11: 145 | D11: 145,2 | E11: confere
A12: FIDC VI | B12: Base subordinada | C12: 37,0 | D12: 36,6 | E12: confere
A13: FIDC VI | B13: Sub / PL | C13: 25% | D13: 25,2% | E13: confere
A14: FIDC VI | B14: Vencidos / Carteira | C14: 11% | D14: 11,5% | E14: confere
A15: FIDC VI | B15: NPL > 90d / Carteira | C15: 6% | D15: 6,5% | E15: confere
A16: FIDC VI | B16: Cobertura PDD / NPL | C16: 584% | D16: 539% | E16: ajustado | F16: Diferença vem do corte do NPL. Incluindo a faixa acima de 720 dias (R$ 1,33 mm) a cobertura é 539%; excluindo-a, 595%.
A17: FIDC VII | B17: PL | C17: 447 | D17: 619,1 | E17: corrigido | F17: O PL de 447 não fecha com a própria linha de base subordinada: 161 ÷ 447 daria 36%, e a planilha traz 26%. Com PL de 619,1 a conta fecha em 26,2%.
A18: FIDC VII | B18: Base subordinada | C18: 161,0 | D18: 162,2 | E18: confere
A19: FIDC VII | B19: Sub / PL | C19: 26% | D19: 26,2% | E19: confere
A20: FIDC VII | B20: Vencidos / Carteira | C20: 0,3% | D20: 0,3% | E20: confere
A21: FIDC VII | B21: NPL > 90d / Carteira | C21: 0,0% | D21: 0,03% | E21: confere
A22: FIDC VII | B22: Cobertura PDD / NPL | C22: 3.724% | D22: 1.565% | E22: ajustado | F22: PDD 2,692 ÷ NPL>90d 0,172. Não encontrei combinação de faixas que reproduza 3.724% em ago/2026.
A23: FIDC VIII | B23: Todos | C23: 750 / 187,5 / 25% | D23: não verificável | E23: aberto | F23: Não há FIDC Solfácil VIII no cadastro da CVM nem no Fundos.NET em 19/10/2026. Os sete fundos do programa são I a VII. Em set/2026 o FIDC VII estava com PL de 718,5 e base subordinada de 187,4 — vale checar se a coluna se refere a ele em data posterior.
A24: FIDC VIII | B24: Tipo | C24: 150 | D24: – | E24: corrigido | F24: A célula trazia 150, que é o valor da linha de exposição. Deixada em branco.
A25: CRI II | B25: Valor total | C25: 750 | D25: 750,0 | E25: confere | F25: Quatro séries públicas de R$ 727,5 mm mais a 5ª série privada de R$ 22,5 mm.
A26: CRI II | B26: Sub / PL | C26: 35% | D26: 35,0% | E26: confere | F26: Abaixo do Super Sênior: Sênior 135,0 + Mezanino 75,0 + Subordinado 30,0 + Subordinado Jr 22,5 = 262,5.
A27: CRI II | B27: Duration | C27: em branco | D27: 14 | E27: preenchido | F27: 1 ano e 2 meses, conforme o informe mensal de CRI de 08/2026.
A28: CRI II | B28: Vencidos / Carteira | C28: em branco | D28: 6,1% | E28: preenchido
A29: CRI II | B29: NPL > 90d / Carteira | C29: em branco | D29: 3,9% | E29: preenchido
A30: CRI II | B30: Cobertura PDD / NPL | C30: em branco | D30: 307% | E30: preenchido | F30: PDD 46,94 ÷ NPL>90d 15,31.
A31: CRI IV | B31: Valor total | C31: 450 | D31: 450,0 | E31: confere | F31: Seis séries públicas de R$ 436,5 mm mais a 7ª série privada de R$ 13,5 mm.
A32: CRI IV | B32: Sub / PL | C32: 35% | D32: 35,0% | E32: confere | F32: Abaixo do Super Sênior A e B: 54,0 + 27,0 + 45,0 + 18,0 + 13,5 = 157,5.
A33: CRI IV | B33: Duration | C33: em branco | D33: 48 | E33: preenchido | F33: 4 anos, conforme o informe de 08/2026. O campo é texto livre e os emissores preenchem de forma inconsistente.
A34: CRI IV | B34: Vencidos / Carteira | C34: em branco | D34: 1,5% | E34: preenchido
A35: CRI IV | B35: NPL > 90d / Carteira | C35: em branco | D35: 0,7% | E35: preenchido
A36: CRI IV | B36: Cobertura PDD / NPL | C36: em branco | D36: 599% | E36: preenchido | F36: PDD 15,80 ÷ NPL>90d 2,64.
A37: CRI VI | B37: Valor total | C37: 456 | D37: 450,0 | E37: ajustado | F37: 450,0 é o integralizado até 31/08/2026; 456 corresponde ao saldo atualizado das séries (457,2). O registro total da oferta é de R$ 647,1 mm com a série privada.
A38: CRI VI | B38: Sub / PL | C38: 16% | D38: 15,0% | E38: corrigido | F38: Abaixo do Sênior A e B: Mezanino I 36,0 + Mezanino II 18,0 + Subordinada 13,5 = 67,5 sobre 450,0.
A39: CRI VI | B39: Duration | C39: em branco | D39: 27 | E39: preenchido | F39: 26,73 meses, conforme o informe de 08/2026.
A40: CRI VI | B40: Vencidos / Carteira | C40: em branco | D40: 0,3% | E40: preenchido | F40: Carteira originada em julho; atraso concentrado na faixa de 1 a 30 dias.
A41: CRI VI | B41: NPL > 90d / Carteira | C41: em branco | D41: 0,0% | E41: preenchido | F41: Nenhum contrato acima de 90 dias.
...
